Workbook

Sheet Summary
A1: MACROADS | B1: 31-11-25 | C1: 45961 | D1: 45930 | E1: 45900 | F1: 45869 | G1: 45838 | H1: 45808 | I1: 45777 | J1: 45747 | K1: 45716 | L1: 45688 | M1: 45657 | N1: 45626 | O1: 45596 | P1: 45565 | Q1: 45535 | R1: 45504 | S1: 45473 | T1: 45443 | U1: 45412 | V1: 45382 | W1: 45351 | X1: 45322 | Y1: 45291 | Z1: 45260 | AA1: 45230 | AB1: 45199 | AC1: 45169 | AD1: 45138 | AE1: 45107 | AF1: 45077 | AG1: 45046 | AH1: 45016 | AI1: 44985 | AJ1: 44957 | AK1: 44926 | AL1: 44802 | AM1: 44742 | AN1: 44712 | AO1: 44286 | AP1: 44561 | AR1: 44377 | AS1: 44012 | AT1: 43646
B2: Actual | C2: Actual | D2: Actual | E2: Actual | F2: Actual | G2: Actual | H2: Actual | I2: Actual | J2: Actual | K2: Actual | L2: Actual | M2: Actual | N2: Actual | O2: Actual | P2: Actual | Q2: Actual | R2: Actual | S2: Actual | T2: Actual | U2: Actual | V2: Actual | W2: Actual | X2: Actual | Y2: Actual | Z2: Actual | AA2: Actual | AB2: Actual | AC2: Actual | AD2: Actual | AE2: Actual | AF2: Actual | AG2: Actual | AH2: Actual | AI2: Actual | AJ2: Actual | AK2: Actual | AL2: Actual | AM2: Actual | AN2: Actual | AO2: Actual | AP2: Actual | AR2: Closing | AS2: Closing | AT2: Closing
A3: South | B3: =+'Clonmel '!AE72 -> 104846.22 | C3: 108197 | D3: 113561 | E3: 125595 | F3: 135797 | G3: 133785.39 | H3: 107568.62 | I3: 94880 | J3: 109489 | K3: 109373 | L3: 106972.55 | M3: 132239.19 | N3: 140595.62 | O3: 141061.21 | P3: 157347.33 | Q3: 106046.23 | R3: 114928.93 | S3: 103349.68 | T3: 100535.13 | U3: 119256.27 | V3: 101772.68 | W3: 139801.8 | X3: 94023.826 | Y3: 79922.806 | Z3: 115965.23 | AA3: 138732.96 | AB3: 100872.14 | AC3: 100476.7 | AD3: 56398.203 | AE3: 94753.329 | AF3: 100100 | AG3: 58025 | AH3: 93755 | AI3: 84571 | AJ3: 113550 | AK3: ='Clonmel '!#REF! -> #REF! | AL3: 92760 | AM3: 97098 | AN3: 53770 | AO3: 60302.5 | AP3: 66837.925 | AR3: 84608 | AS3: 131937.67 | AT3: 99087.5
A4: Dublin | B4: =+Dublin!T86 -> 45421.085 | C4: 47350 | D4: 56917 | E4: 50926 | F4: 51975 | G4: 61990.17 | H4: 59066.795 | I4: 57285 | J4: 47926 | K4: 51267 | L4: 45472.792 | M4: 47311 | N4: 47939.32 | O4: 48777.94 | P4: 59098.93 | Q4: 51641.015 | R4: 80255.895 | S4: 62873.28 | T4: 56989.71 | U4: 71342.115 | V4: 55712.41 | W4: 46125.445 | X4: 48360.75 | Y4: 31502.815 | Z4: 38084.84 | AA4: 51351.57 | AB4: 37183.39 | AC4: 43436.555 | AD4: 43150.32 | AE4: 52976.125 | AF4: 48469 | AG4: 45475 | AH4: 32076 | AI4: 36342 | AJ4: 42096 | AK4: 42853 | AL4: 28239 | AM4: 38870 | AN4: 20970.586 | AO4: 32914.157 | AP4: =Dublin!#REF! -> #REF! | AR4: 50000 | AS4: 49952.5 | AT4: 34400
A5: Total Stock | B5: =B3+B4 -> 150267.3 | C5: =C3+C4 -> 155547 | D5: =D3+D4 -> 170478 | E5: =E3+E4 -> 176521 | F5: =F3+F4 -> 187772 | G5: =G3+G4 -> 195775.56 | H5: =H3+H4 -> 166635.42 | I5: =I3+I4 -> 152165 | ... AP5: =AP3+AP4 -> #REF! | AR5: =AR3+AR4 -> 134608 | AS5: =AS3+AS4 -> 181890.17 | AT5: =AT3+AT4 -> 133487.5
A7: MoM Variance | B7: =+B5-C5 -> -5279.6953 | C7: =+C5-D5 -> -14931 | D7: =+D5-E5 -> -6043 | E7: 11251 | F7: =+F5-G5 -> -8003.5629 | G7: =+G5-H5 -> 29140.144 | H7: =+H5-I5 -> 14470.419 | I7: =+I5-J5 -> -5250 | J7: =+J5-K5 -> -3225 | K7: =+K5-L5 -> 8194.6551 | L7: -27137.69 | M7: -7788.7218 | N7: -1304.2159 | O7: -27802.812 | P7: =+P5-Q5 -> 58759.015 | Q7: =+Q5-R5 -> -37497.577 | R7: =+R5-S5 -> 28961.866 | S7: =+S5-T5 -> 8698.1241 | T7: =+T5-U5 -> -33073.546 | U7: =+U5-V5 -> 33113.295 | V7: =+V5-W5 -> -28442.156 | W7: =+W5-X5 -> 43542.667 | ... AK7: =+AK5-AL5 -> #REF!
A9: YoY Variance | B9: =+B5-M5 -> -29282.881 | C9: =+C5-N5 -> -32987.937 | D9: =+D5-P5 -> -45968.265 | E9: 18833 | F9: =+F5-R5 -> -7412.8264 | G9: =+G5-S5 -> 29552.603 | H9: =+H5-T5 -> 9110.5827 | I9: =+I5-U5 -> -38433.382 | J9: =+J5-V5 -> -70.086897 | K9: =+K5-W5 -> -25287.243 | L9: 10028.249 | M9: 68124.894 | N9: 33289.162 | O9: -1441.0722 | P9: =+P5-AB5 -> 78390.734 | Q9: =+Q5-AC5 -> 13773.994 | R9: =+R5-AD5 -> 95636.303 | S9: =+S5-AE5 -> 18493.506
A11: Clonmel | B11: =+B3-C3 -> -3350.7803 | C11: =+C3-D3 -> -5364 | D11: =+D3-E3 -> -12034 | E11: -10202 | F11: =+F3-G3 -> 2011.6071 | G11: =+G3-H3 -> 26216.769 | H11: =+H3-I3 -> 12688.624 | I11: =+I3-J3 -> -14609 | J11: =+J3-K3 -> 116 | K11: =+K3-L3 -> 2400.4476 | L11: -25266.633 | M11: -8356.4318 | N11: -465.59588 | O11: -16286.122 | P11: =+P3-Q3 -> 51301.1 | Q11: =+Q3-R3 -> -8882.6966 | R11: =+R3-S3 -> 11579.251
A12: Dublin | B12: =+B4-C4 -> -1928.915 | C12: =+C4-D4 -> -9567 | D12: =+D4-E4 -> 5991 | E12: -1049 | F12: =+F4-G4 -> -10015.17 | G12: =+G4-H4 -> 2923.375 | H12: =+H4-I4 -> 1781.795 | I12: =+I4-J4 -> 9359 | J12: =+J4-K4 -> -3341 | K12: =+K4-L4 -> 5794.2075 | L12: -1871.0575 | M12: 567.71 | N12: -838.62 | O12: -11516.69 | P12: =+P4-Q4 -> 7457.915 | Q12: =+Q4-R4 -> -28614.88 | R12: =+R4-S4 -> 17382.615
A13: Additional Dublin m/ment re March
A14: Total M/ment | B14: =SUM(B11:B13) -> -5279.6953 | C14: =SUM(C11:C13) -> -14931 | D14: =SUM(D11:D13) -> -6043 | E14: =SUM(E11:E13) -> -11251 | F14: =SUM(F11:F13) -> -8003.5629 | G14: =SUM(G11:G13) -> 29140.144 | H14: =SUM(H11:H13) -> 14470.419 | I14: =SUM(I11:I13) -> -5250 | ... K14: =SUM(K11:K13) -> 8194.6551 | L14: -27137.69 | M14: -7788.7218 | N14: -1304.2159 | O14: -27802.812 | P14: =SUM(P11:P13) -> 58759.015 | Q14: =SUM(Q11:Q13) -> -37497.577 | R14: =SUM(R11:R13) -> 28961.866
A16: Bal per nl | B16: =+C20 -> 155551 | C16: =+D20 -> 170481 | D16: =+E20 -> 176523 | E16: 187773 | F16: =+G20 -> 195776.14 | G16: 166635 | H16: =+I20 -> 152166 | I16: =+J20 -> 157415 | J16: 160639 | K16: 152412 | L16: 179549.52 | M16: 187339.24 | N16: 188643.45 | O16: 164952 | P16: 164952 | Q16: 195627 | R16: 159441
A17: Clonmel m/.ment | B17: =+B11 -> -3350.7803 | C17: =+C11 -> -5364 | D17: =+D11 -> -12034 | E17: -10202 | F17: =+F11 -> 2011.6071 | G17: =+G11 -> 26216.769 | H17: =+H11 -> 12688.624 | I17: =+I11 -> -14609 | J17: =+J11 -> 116 | K17: =+K11 -> 2400.4476 | L17: -25265.633 | M17: -8356.4318 | N17: -465.59588 | O17: -16286.122 | P17: =+P11 -> 51301.1 | Q17: =+Q11 -> -8882.6966 | R17: =+R11 -> 11579.251
A18: Dublin m/ment | B18: =+B12+1 -> -1927.915 | C18: =+C12+1 -> -9566 | D18: =+D12+1 -> 5992 | E18: -1048 | F18: =+F12+1 -> -10014.17 | G18: =+G12+1 -> 2924.375 | H18: =+H12+1 -> 1782.795 | I18: =+I12+1 -> 9360 | J18: =+J12+1 -> -3340 | K18: =+K12 -> 5794.2075 | L18: -1871.0575 | M18: 567.71 | N18: -838.62 | O18: -11516.69 | P18: =+P12 -> 7457.915 | Q18: =+Q12 -> -28614.88 | R18: =+R12 -> 17382.615
A19: Dublin diff | K19: -1 | L19: -1 | R19: 1
A20: Bal per nl | B20: =SUM(B16:B19) -> 150272.3 | C20: =SUM(C16:C19) -> 155551 | D20: =SUM(D16:D19) -> 170481 | E20: =SUM(E16:E19) -> 176523 | F20: =SUM(F16:F19) -> 187773.58 | G20: =SUM(G16:G19) -> 195776.14 | H20: =SUM(H16:H19) -> 166637.42 | I20: =SUM(I16:I19) -> 152166 | ... L20: =SUM(L16:L19) -> 152411.82 | M20: 179550.52 | N20: 187339.24 | O20: 137149.19 | P20: =SUM(P16:P19) -> 223711.02 | Q20: =SUM(Q16:Q19) -> 158129.42 | R20: =SUM(R16:R19) -> 188403.87
K21: 3225
K22: =+K20-K21 -> 157380.66

Sheet Dublin
A1: Dublin Yard Stock | G1: 45807 | I1: 45838 | K1: 45869 | M1: 45901 | O1: 45931 | Q1: 45961 | S1: 45991 | U1: 46387 | W1: 46053 | Y1: 46081 | AA1: 46112 | AC1: 46142 | AE1: 46173 | AG1: 46203 | AI1: 46234
A2: Description | B2: Supplier | C2: Type | D2: Unit | E2: 2025 Prices | G2: Qty | H2: Value | I2: Qty | J2: Value | K2: Qty | L2: Value | M2: Qty | N2: Value | O2: Qty | P2: Value | Q2: Qty | R2: Value | S2: Qty | T2: Value | U2: Qty | V2: Value | W2: Qty | X2: Value | Y2: Qty | Z2: Value | AA2: Qty | AB2: Value | AC2: Qty | AD2: Value | AE2: Qty | AF2: Value | AG2: Qty | AH2: Value | AI2: Qty | AJ2: Value | AK2: Qty | AL2: Value
A3: White Extrusion 80/20 | B3: Kestrel | C3: Thermo-P | D3: Tonne | E3: 890 | G3: 9.83 | H3: =+G3*E3 -> 8748.7 | I3: 16.6 | J3: =+I3*E3 -> 14774 | K3: 9.21 | L3: =+K3*E3 -> 8196.9 | M3: 2.41 | N3: =+M3*E3 -> 2144.9 | O3: 14.41 | P3: =+O3*E3 -> 12824.9 | Q3: 11.23 | R3: =+Q3*E3 -> 9994.7 | S3: 9.19 | T3: =+S3*E3 -> 8179.1 | U3: 21.6128 | V3: =+U3*E3 -> 19235.392 | W3: 10.9728 | X3: 9765.792 | Y3: 8.5 | Z3: =+Y3*E3 -> 7565 | AA3: 5.02 | AB3: =+AA3*E3 -> 4467.8 | AC3: 3.09 | AD3: =+AC3*[1]Dublin!E3 -> 2750.1 | AE3: 3.86 | AF3: =AE3*E3 -> 3435.4 | AG3: =+AS90 -> 7.52 | AH3: =AG3*E3 -> 6692.8 | AI3: =AS90 -> 7.52 | AJ3: =AI3*E3 -> 6692.8 | AK3: =AS90 -> 7.52 | AL3: =AK3*E3 -> 6692.8
A4: Yellow Extrusion 55/20 | B4: Kestrel | C4: Thermo-P | D4: Tonne | E4: 930 | G4: 11.23 | H4: =+G4*E4 -> 10443.9 | I4: 14.82 | J4: =+I4*E4 -> 13782.6 | K4: 13.01 | L4: =+K4*E4 -> 12099.3 | M4: 11.2 | N4: =+M4*E4 -> 10416 | O4: 8.14 | P4: =+O4*E4 -> 7570.2 | Q4: 5.7 | R4: =+Q4*E4 -> 5301 | S4: 3.506 | T4: =+S4*E4 -> 3260.58 | U4: 11.8172 | V4: =+U4*E4 -> 10989.996 | W4: 7.5616 | X4: 7032.288 | Y4: 6.96 | Z4: =+Y4*E4 -> 6472.8 | AA4: 5.75 | AB4: =+AA4*E4 -> 5347.5 | AC4: 2.85 | AD4: =+AC4*[1]Dublin!E4 -> 2650.5 | AE4: 6.78 | AF4: =AE4*E4 -> 6305.4 | AG4: =+AW90 -> 10.02 | AH4: =AG4*E4 -> 9318.6 | AI4: =AW90 -> 10.02 | AJ4: =E4*AI4 -> 9318.6 | AK4: =AW90 -> 10.02 | AL4: =AK4*E4 -> 9318.6
A5: Unpigmented Screed | B5: Kestrel | C5: Thermo-P | D5: Tonne | E5: 930 | G5: 0.7 | H5: =+G5*E5 -> 651 | I5: 0.7 | J5: =+I5*E5 -> 651 | K5: 0.7 | L5: =+K5*E5 -> 651 | M5: 0.68 | N5: =+M5*E5 -> 632.4 | O5: 0.68 | P5: =+O5*E5 -> 632.4 | Q5: 0.68 | R5: =+Q5*E5 -> 632.4 | S5: 0.6 | T5: =+S5*E5 -> 558 | V5: =+U5*E5 -> 0 | W5: 0.6 | X5: 558 | Y5: 0.6 | Z5: =+Y5*E5 -> 558 | AB5: =+AA5*E5 -> 0 | AD5: =+AC5*[1]Dublin!E5 -> 0 | AF5: =AE5*E5 -> 0 | AG5: 0.5 | AH5: =AG5*E5 -> 465 | AJ5: =AI5*G5 -> 0
A6: Buff - KestrelFlex - Anti-Skid | B6: Kestrel | C6: A-S | D6: Tonne | E6: 1125 | G6: 0 | H6: =+G6*E6 -> 0 | J6: =+I6*E6 -> 0 | K6: 0 | L6: =+K6*E6 -> 0 | M6: 2 | N6: =+M6*E6 -> 2250 | O6: 3 | P6: =+O6*E6 -> 3375 | Q6: 2.22 | R6: =+Q6*E6 -> 2497.5 | S6: 0 | T6: =+S6*E6 -> 0 | V6: =+U6*E6 -> 0 | W6: 0 | X6: 0 | Z6: =+Y6*E6 -> 0 | AB6: =+AA6*E6 -> 0 | AD6: =+AC6*[1]Dublin!E6 -> 0 | AF6: =AE6*E6 -> 0 | AH6: =AG6*E6 -> 0 | AJ6: =AI6*G6 -> 0
A7: Red - KestrelFlex - Anti-Skid | B7: Kestrel | C7: A-S | D7: Tonne | E7: 885 | G7: 6.25 | H7: =+G7*E7 -> 5531.25 | I7: 6.25 | J7: =+I7*E7 -> 5531.25 | K7: 6.25 | L7: =+K7*E7 -> 5531.25 | M7: 6.25 | N7: =+M7*E7 -> 5531.25 | O7: 4 | P7: =+O7*E7 -> 3540 | R7: =+Q7*E7 -> 0 | S7: 2.22 | T7: =+S7*E7 -> 1964.7 | U7: 2.22 | V7: =+U7*E7 -> 1964.7 | W7: 2.2 | X7: 1947 | Y7: 2.2 | Z7: =+Y7*E7 -> 1947 | AA7: 2.2 | AB7: =+AA7*E7 -> 1947 | AD7: =+AC7*[1]Dublin!E7 -> 0 | AE7: 2.2 | AF7: =AE7*E7 -> 1947 | AG7: 2.2 | AH7: =AG7*E7 -> 1947 | AI7: 2.2 | AJ7: =AI7*E7 -> 1947 | AK7: 2.2 | AL7: =AK7*E7 -> 1947
A8: Bitumen | B8: Kestrel | C8: A-S | D8: Tonne | E8: 450 | G8: 0 | H8: =+G8*E8 -> 0 | J8: =+I8*E8 -> 0 | K8: 0 | L8: =+K8*E8 -> 0 | M8: 1 | N8: =+M8*E8 -> 450 | P8: =+O8*E8 -> 0 | R8: =+Q8*E8 -> 0 | S8: 0 | T8: =+S8*E8 -> 0 | V8: =+U8*E8 -> 0 | W8: 0 | X8: 0 | Z8: =+Y8*E8 -> 0 | AB8: =+AA8*E8 -> 0 | AD8: =+AC8*[1]Dublin!E8 -> 0 | AF8: =AE8*E8 -> 0 | AH8: =AG8*E8 -> 0 | AJ8: =AI8*E8 -> 0
A9: Ultraforce L247 MMA Kit (3 Part Kit) | B9: Meon | C9: Cold A-S | E9: 173.29 | G9: 34 | H9: =+G9*E9 -> 5891.86 | I9: 10 | J9: =+I9*E9 -> 1732.9 | K9: 10 | L9: =+K9*E9 -> 1732.9 | M9: 10 | N9: =+M9*E9 -> 1732.9 | O9: 10 | P9: =+O9*E9 -> 1732.9 | Q9: 10 | R9: =+Q9*E9 -> 1732.9 | S9: 10 | T9: =+S9*E9 -> 1732.9 | U9: 10 | V9: =+U9*E9 -> 1732.9 | W9: 10 | X9: 1732.9 | Y9: 10 | Z9: =+Y9*E9 -> 1732.9 | AA9: 10 | AB9: =+AA9*E9 -> 1732.9 | AC9: 10 | AD9: =+AC9*[1]Dublin!E9 -> 1732.9 | AE9: 10 | AF9: =AE9*E9 -> 1732.9 | AG9: 3 | AH9: =AG9*E9 -> 519.87 | AI9: 3 | AJ9: =AI9*E9 -> 519.87
A10: Bauxite Buff for MMA | B10: Meon | C10: Cold A-S | D10: 20 Kg | E10: 33.09 | G10: 0 | H10: =+G10*E10 -> 0 | J10: =+I10*E10 -> 0 | L10: =+K10*E10 -> 0 | N10: =+M10*E10 -> 0 | P10: =+O10*E10 -> 0 | R10: =+Q10*E10 -> 0 | S10: 0 | T10: =+S10*E10 -> 0 | V10: =+U10*E10 -> 0 | W10: 0 | X10: 0 | Z10: =+Y10*E10 -> 0 | AB10: =+AA10*E10 -> 0 | AD10: =+AC10*[1]Dublin!E10 -> 0 | AF10: =AE10*E10 -> 0 | AH10: =AG10*E10 -> 0 | AJ10: =AI10*E10 -> 0
A11: Aggregate for Red MMA A/S | B11: Meon | C11: Cold A-S | D11: Tonne | E11: 1310 | G11: 1.5 | H11: =+G11*E11 -> 1965 | I11: 1.5 | J11: =+I11*E11 -> 1965 | K11: 1 | L11: =+K11*E11 -> 1310 | M11: 1 | N11: =+M11*E11 -> 1310 | O11: 1 | P11: =+O11*E11 -> 1310 | Q11: 1 | R11: =+Q11*E11 -> 1310 | S11: 1 | T11: =+S11*E11 -> 1310 | U11: 1 | V11: =+U11*E11 -> 1310 | W11: 1 | X11: 1310 | Y11: 1 | Z11: =+Y11*E11 -> 1310 | AB11: =+AA11*E11 -> 0 | AD11: =+AC11*[1]Dublin!E11 -> 0 | AF11: =AE11*E11 -> 0 | AG11: 0.333 | AH11: =AG11*E11 -> 436.23 | AJ11: =AI11*E11 -> 0
A12: Anti-skid re-instatement | B12: Meon | C12: Cold A-S | D12: 20kgs | G12: 24 | H12: =+G12*E12 -> 0 | I12: 24 | J12: =+I12*E12 -> 0 | K12: 24 | L12: =+K12*E12 -> 0 | M12: 24 | N12: =+M12*E12 -> 0 | O12: 24 | P12: =+O12*E12 -> 0 | R12: =+Q12*E12 -> 0 | S12: 0 | T12: =+S12*E12 -> 0 | V12: =+U12*E12 -> 0 | X12: 0 | Z12: =+Y12*E12 -> 0 | AB12: =+AA12*E12 -> 0 | AC12: 24 | AD12: =+AC12*[1]Dublin!E12 -> 0 | AE12: 24 | AF12: =AE12*E12 -> 0 | AG12: 24 | AH12: =AG12*E12 -> 0 | AI12: 24 | AJ12: =AI12*E12 -> 0 | AK12: 24
A13: Beads | B13: Kestrel | C13: Beads | D13: Tonne | E13: 790 | G13: 0.45 | H13: =+G13*E13 -> 355.5 | I13: 0.225 | J13: =+I13*E13 -> 177.75 | K13: 0.66 | L13: =+K13*E13 -> 521.4 | M13: 0.75 | N13: =+M13*E13 -> 592.5 | P13: =+O13*E13 -> 0 | Q13: =+#REF! -> #REF! | R13: =+Q13*E13 -> #REF! | S13: 0.4 | T13: =+S13*E13 -> 316 | U13: =+#REF! -> #REF! | V13: =+U13*E13 -> #REF! | W13: 1.075 | X13: 849.25 | Y13: 1 | Z13: =+Y13*E13 -> 790 | AA13: 0.4 | AB13: =+AA13*E13 -> 316 | AC13: 1.9 | AD13: =+AC13*[1]Dublin!E13 -> 1501 | AF13: =AE13*E13 -> 0 | AG13: 2 | AH13: =AG13*E13 -> 1580 | AI13: 2 | AJ13: =AI13*E13 -> 1580 | AK13: 0.5 | AL13: =AK13*E13 -> 395
A14: Ramp Pieces (M & E) | B14: M & E | C14: F&F | D14: 1 Unit | E14: 17.5 | G14: 16 | H14: =+G14*E14 -> 280 | J14: =+I14*E14 -> 0 | L14: =+K14*E14 -> 0 | M14: 16 | N14: =+M14*E14 -> 280 | O14: 16 | P14: =+O14*E14 -> 280 | Q14: 16 | R14: =+Q14*E14 -> 280 | S14: 16 | T14: =+S14*E14 -> 280 | U14: 16 | V14: =+U14*E14 -> 280 | W14: 16 | X14: 280 | Z14: =+Y14*E14 -> 0 | AB14: =+AA14*E14 -> 0 | AD14: =+AC14*[1]Dublin!E16 -> 0 | AF14: =AE14*E14 -> 0 | AH14: =AG14*E14 -> 0 | AJ14: =AI14*E14 -> 0
A15: Bollards | B15: M & E | C15: F&F | D15: 1 Unit | E15: 25 | G15: 3 | H15: =+G15*E15 -> 75 | J15: =+I15*E15 -> 0 | L15: =+K15*E15 -> 0 | M15: 3 | N15: =+M15*E15 -> 75 | O15: 3 | P15: =+O15*E15 -> 75 | Q15: 3 | R15: =+Q15*E15 -> 75 | S15: 3 | T15: =+S15*E15 -> 75 | U15: 3 | V15: =+U15*E15 -> 75 | W15: 3 | X15: 75 | Y15: 3 | Z15: =+Y15*E15 -> 75 | AB15: =+AA15*E15 -> 0 | AD15: =+AC15*[1]Dublin!E17 -> 0 | AF15: =AE15*E15 -> 0 | AH15: =AG15*E15 -> 0 | AJ15: =AI15*E15 -> 0
A16: Bicycle Logo's 1200mm | B16: Kestrel | C16: Logo | D16: 1 Unit | E16: 20 | G16: 54 | H16: =+G16*E16 -> 1080 | I16: 49 | J16: =+I16*E16 -> 980 | K16: 59 | L16: =+K16*E16 -> 1180 | M16: 30 | N16: =+M16*E16 -> 600 | O16: 34 | P16: =+O16*E16 -> 680 | Q16: =20+25-8 -> 37 | R16: =+Q16*E16 -> 740 | S16: 175 | T16: =+S16*E16 -> 3500 | U16: 175 | V16: =+U16*E16 -> 3500 | W16: 110 | X16: 2200 | Y16: =74+35 -> 109 | Z16: =+Y16*E16 -> 2180 | AA16: 63 | AB16: =+AA16*E16 -> 1260 | AC16: 28 | AD16: =+AC16*[1]Dublin!E18 -> 560 | AE16: 17 | AF16: =AE16*E16 -> 340 | AG16: =2+15+4+30+27+35 -> 113 | AH16: =AG16*E16 -> 2260 | AI16: 16 | AJ16: =AI16*E16 -> 320 | AK16: 130 | AL16: =AK16*E16 -> 2600
A17: Bicycle Logo's 2750mm | B17: Kestrel | C17: Logo | D17: 1 Unit | E17: 95 | G17: 14 | H17: =+G17*E17 -> 1330 | I17: 7 | J17: =+I17*E17 -> 665 | K17: 4 | L17: =+K17*E17 -> 380 | M17: 2 | N17: =+M17*E17 -> 190 | O17: 10 | P17: =+O17*E17 -> 950 | Q17: 12 | R17: =+Q17*E17 -> 1140 | S17: 16 | T17: =+S17*E17 -> 1520 | U17: 17 | V17: =+U17*E17 -> 1615 | W17: 31 | X17: 2945 | Y17: 31 | Z17: =+Y17*E17 -> 2945 | AA17: 33 | AB17: =+AA17*E17 -> 3135 | AC17: 17 | AD17: =+AC17*[1]Dublin!E19 -> 1615 | AE17: 17 | AF17: =AE17*E17 -> 1615 | AG17: 11 | AH17: =AG17*E17 -> 1045 | AI17: 11 | AJ17: =AI17*E17 -> 1045 | AK17: 41 | AL17: =AK17*E17 -> 3895
A18: Bicycle Logo's 1200mm | B18: Kellys | C18: Logo | AA18: 30 | AC18: 33 | AD18: =+AC18*[1]Dublin!E20 -> 0 | AF18: =AE18*E18 -> 0 | AH18: =AG18*E18 -> 0 | AI18: 65 | AJ18: =AI18*E18 -> 0
A19: Disabled Logo on Purple B'ground | B19: Kestrel | C19: Logo | D19: 1 Unit | E19: 125 | Q19: 1 | R19: =+Q19*E19 -> 125 | S19: 1 | T19: =+S19*E19 -> 125 | U19: 1 | V19: =+U19*E19 -> 125 | W19: 1 | X19: 125 | Y19: 1 | Z19: =+Y19*E19 -> 125 | AA19: 1 | AB19: =+AA19*E19 -> 125 | AD19: =+AC19*[1]Dublin!E21 -> 0 | AF19: =AE19*E19 -> 0 | AH19: =AG19*E19 -> 0 | AJ19: =AI19*E19 -> 0
A20: E Car Logo Large | B20: Kestrel | C20: Logo | D20: 1 Unit | E20: 50 | G20: 2 | H20: =+G20*E20 -> 100 | I20: 2 | J20: =+I20*E20 -> 100 | K20: 2 | L20: =+K20*E20 -> 100 | M20: 2 | N20: =+M20*E20 -> 100 | O20: 2 | P20: =+O20*E20 -> 100 | Q20: 1 | R20: =+Q20*E20 -> 50 | S20: 1 | T20: =+S20*E20 -> 50 | U20: 1 | V20: =+U20*E20 -> 50 | W20: 1 | X20: 50 | Z20: =+Y20*E20 -> 0 | AB20: =+AA20*E20 -> 0 | AD20: =+AC20*[1]Dublin!E22 -> 0 | AF20: =AE20*E20 -> 0 | AH20: =AG20*E20 -> 0 | AJ20: =AI20*E20 -> 0
A21: E Car Logo Small 1.2M | B21: Kestrel | C21: Logo | D21: 1 Unit | E21: 40 | G21: 21 | H21: =+G21*E21 -> 840 | I21: 24 | J21: =+I21*E21 -> 960 | K21: 22 | L21: =+K21*E21 -> 880 | M21: 22 | N21: =+M21*E21 -> 880 | O21: 19 | P21: =+O21*E21 -> 760 | Q21: =5+16 -> 21 | R21: =+Q21*E21 -> 840 | S21: 17 | T21: =+S21*E21 -> 680 | U21: 17 | V21: =+U21*E21 -> 680 | W21: 7 | X21: 280 | Z21: =+Y21*E21 -> 0 | AA21: 2 | AB21: =+AA21*E21 -> 80 | AD21: =+AC21*[1]Dublin!E23 -> 0 | AE21: 2 | AF21: =AE21*E21 -> 80 | AG21: 3 | AH21: =AG21*E21 -> 120 | AJ21: =AI21*E21 -> 0
A22: E Car Logo 1.0m | B22: Kestrel | C22: Logo | D22: 1 Unit | E22: 40 | G22: 21 | H22: =+G22*E22 -> 840 | I22: 24 | J22: =+I22*E22 -> 960 | K22: 22 | L22: =+K22*E22 -> 880 | M22: 22 | N22: =+M22*E22 -> 880 | O22: 19 | P22: =+O22*E22 -> 760 | Q22: =5+16 -> 21 | R22: =+Q22*E22 -> 840 | S22: 17 | T22: =+S22*E22 -> 680 | V22: =+U22*E22 -> 0 | W22: 20 | X22: 800 | Y22: 20 | Z22: =+Y22*E22 -> 800 | AA22: 20 | AB22: =+AA22*E22 -> 800 | AC22: 22 | AD22: =+AC22*[1]Dublin!E24 -> 880 | AE22: 20 | AF22: =AE22*E22 -> 800 | AG22: =15+4 -> 19 | AH22: =AG22*E22 -> 760 | AJ22: =AI22*E22 -> 0 | AK22: 15 | AL22: =AK22*E22 -> 600
A23: E Car Logo Small c/w Green Background | B23: Kestrel | C23: Logo | D23: 1 Unit | E23: 125 | G23: 6 | H23: =+G23*E23 -> 750 | I23: 5 | J23: =+I23*E23 -> 625 | K23: 5 | L23: =+K23*E23 -> 625 | M23: 5 | N23: =+M23*E23 -> 625 | O23: 18 | P23: =+O23*E23 -> 2250 | Q23: =4+13 -> 17 | R23: =+Q23*E23 -> 2125 | S23: 17 | T23: =+S23*E23 -> 2125 | U23: 17 | V23: =+U23*E23 -> 2125 | W23: 16 | X23: 2000 | Y23: =1+15 -> 16 | Z23: =+Y23*E23 -> 2000 | AA23: 13 | AB23: =+AA23*E23 -> 1625 | AC23: 13 | AD23: =+AC23*[1]Dublin!E25 -> 1625 | AE23: 13 | AF23: =AE23*E23 -> 1625 | AG23: 13 | AH23: =AG23*E23 -> 1625 | AI23: 13 | AJ23: =AI23*E23 -> 1625
A24: E Car Logo for epower | B24: Kestrel | C24: Logo | D24: 1 Unit | E24: 150 | G24: 6 | H24: =+G24*E24 -> 900 | I24: 5 | J24: =+I24*E24 -> 750 | K24: 5 | L24: =+K24*E24 -> 750 | M24: 5 | N24: =+M24*E24 -> 750 | O24: 18 | P24: =+O24*E24 -> 2700 | Q24: =4+13 -> 17 | R24: =+Q24*E24 -> 2550 | S24: 17 | T24: =+S24*E24 -> 2550 | V24: =+U24*E24 -> 0 | W24: 8 | X24: 1200 | Y24: 8 | Z24: =+Y24*E24 -> 1200 | AA24: 8 | AB24: =+AA24*E24 -> 1200 | AD24: =+AC24*[1]Dublin!E26 -> 0 | AF24: =AE24*E24 -> 0 | AH24: =AG24*E24 -> 0 | AJ24: =AI24*E24 -> 0
A25: Motorcycle Logo | B25: Kestrel | C25: Logo | D25: 1 Unit | E25: 45 | G25: 8 | H25: =+G25*E25 -> 360 | I25: 8 | J25: =+I25*E25 -> 360 | K25: 8 | L25: =+K25*E25 -> 360 | M25: 8 | N25: =+M25*E25 -> 360 | O25: 8 | P25: =+O25*E25 -> 360 | Q25: 8 | R25: =+Q25*E25 -> 360 | S25: 8 | T25: =+S25*E25 -> 360 | U25: 8 | V25: =+U25*E25 -> 360 | W25: 8 | X25: 360 | Y25: 8 | Z25: =+Y25*E25 -> 360 | AA25: 9 | AB25: =+AA25*E25 -> 405 | AC25: 9 | AD25: =+AC25*[1]Dublin!E27 -> 405 | AE25: 9 | AF25: =AE25*E25 -> 405 | AG25: 9 | AI25: 9 | AJ25: =AI25*E25 -> 405 | AK25: 9 | AL25: =AK25*E25 -> 405
A26: Mother & Child Black | B26: Kestrel | C26: Logo | D26: 1 Unit | E26: 55 | G26: 8 | H26: =+G26*E26 -> 440 | I26: 8 | J26: =+I26*E26 -> 440 | K26: 8 | L26: =+K26*E26 -> 440 | M26: 8 | N26: =+M26*E26 -> 440 | O26: 5 | P26: =+O26*E26 -> 275 | Q26: 5 | R26: =+Q26*E26 -> 275 | S26: 5 | T26: =+S26*E26 -> 275 | U26: 5 | V26: =+U26*E26 -> 275 | W26: 5 | X26: 275 | Y26: 4 | Z26: =+Y26*E26 -> 220 | AA26: 5 | AB26: =+AA26*E26 -> 275 | AC26: 5 | AD26: =+AC26*[1]Dublin!E28 -> 275 | AE26: 5 | AF26: =AE26*E26 -> 275 | AG26: 5 | AH26: =AG26*E26 -> 275 | AI26: 5 | AJ26: =AI26*E26 -> 275
A27: Pedestrian Logo's 1,200mm * 700mm | B27: Kestrel | C27: Logo | D27: 1 Unit | E27: 20 | G27: 21 | H27: =+G27*E27 -> 420 | I27: =41 -> 41 | J27: =+I27*E27 -> 820 | K27: 83 | L27: =+K27*E27 -> 1660 | M27: 52 | N27: =+M27*E27 -> 1040 | O27: 98 | P27: =+O27*E27 -> 1960 | Q27: =20+17+3 -> 40 | R27: =+Q27*E27 -> 800 | S27: 58 | T27: =+S27*E27 -> 1160 | U27: 50 | V27: =+U27*E27 -> 1000 | W27: 31 | X27: 620 | Y27: 16 | Z27: =+Y27*E27 -> 320 | AA27: 15 | AB27: =+AA27*E27 -> 300 | AC27: 12 | AD27: =+AC27*[1]Dublin!E29 -> 240 | AE27: 56 | AF27: =AE27*E27 -> 1120 | AG27: 54 | AH27: =AG27*E27 -> 1080 | AJ27: =AI27*E27 -> 0 | AK27: 90 | AL27: =AK27*E27 -> 1800
A28: Pedestrian Logo 1200mm in YELLOW | B28: Kellys | C28: Logo | D28: 2 Unit | E28: 22.5 | Q28: 26 | R28: =+Q28*E28 -> 585 | S28: 24 | T28: =+S28*E28 -> 540 | U28: 24 | V28: =+U28*E28 -> 540 | W28: 16 | X28: 360 | Y28: 16 | Z28: =+Y28*E28 -> 360 | AA28: 23 | AB28: =+AA28*E28 -> 517.5 | AD28: =+AC28*[1]Dublin!E30 -> 0 | AE28: 53 | AF28: =AE28*E28 -> 1192.5 | AG28: 46 | AH28: =AG28*E28 -> 1035 | AI28: 46 | AJ28: =AI28*E28 -> 1035 | AK28: 25 | AL28: =AK28*E28 -> 562.5
A29: Pedestrian Logo White | B29: Kellys | C29: Logo | AA29: 34 | AC29: 34 | AD29: =+AC29*[1]Dublin!E31 -> 0 | AF29: =AE29*E29 -> 0 | AH29: =AG29*E29 -> 0 | AJ29: =AI29*E29 -> 0 | AK29: ?
A30: Pedestrian Logo's 980mm | B30: Kestrel | C30: Logo | D30: 1 Unit | E30: 15 | G30: 30 | H30: =+G30*E30 -> 450 | I30: 33 | J30: =+I30*E30 -> 495 | K30: 12 | L30: =+K30*E30 -> 180 | M30: 12 | N30: =+M30*E30 -> 180 | O30: 12 | P30: =+O30*E30 -> 180 | R30: =+Q30*E30 -> 0 | S30: 55 | T30: =+S30*E30 -> 825 | U30: 55 | V30: =+U30*E30 -> 825 | W30: 50 | X30: 750 | Y30: 50 | Z30: =+Y30*E30 -> 750 | AA30: 50 | AB30: =+AA30*E30 -> 750 | AC30: 45 | AD30: =+AC30*[1]Dublin!E32 -> 675 | AE30: 58 | AF30: =AE30*E30 -> 870 | AG30: 45 | AH30: =AG30*E30 -> 675 | AI30: 35 | AJ30: =AI30*E30 -> 525 | AK30: 35 | AL30: =AK30*E30 -> 525
A31: Pre-form for Lucan ETNS | B31: Kestrel | C31: Logo | D31: 1 Unit | E31: 2252.8 | G31: 0 | H31: =+G31*E31 -> 0 | J31: =+I31*E31 -> 0 | K31: 0 | L31: =+K31*E31 -> 0 | M31: 1 | N31: =+M31*E31 -> 2252.8 | O31: 1 | P31: =+O31*E31 -> 2252.8 | Q31: 1 | R31: =+Q31*E31 -> 2252.8 | S31: 0 | T31: =+S31*E31 -> 0 | V31: =+U31*E31 -> 0 | W31: 1 | X31: 2252.8 | Z31: =+Y31*E31 -> 0 | AB31: =+AA31*E31 -> 0 | AD31: =+AC31*[1]Dublin!E33 -> 0 | AF31: =AE31*E31 -> 0 | AH31: =AG31*E31 -> 0 | AJ31: =AI31*E31 -> 0 | AL31: =AK31*E31 -> 0
A32: Parent & Child Logos (IKEA) | B32: Kestrel | C32: Logo | D32: 1 Unit | E32: 65 | G32: 3 | H32: =+G32*E32 -> 195 | I32: 3 | J32: =+I32*E32 -> 195 | K32: 3 | L32: =+K32*E32 -> 195 | M32: 3 | N32: =+M32*E32 -> 195 | O32: 3 | P32: =+O32*E32 -> 195 | Q32: 3 | R32: =+Q32*E32 -> 195 | S32: 3 | T32: =+S32*E32 -> 195 | U32: 3 | V32: =+U32*E32 -> 195 | W32: 3 | X32: 195 | Y32: 3 | Z32: =+Y32*E32 -> 195 | AA32: 3 | AB32: =+AA32*E32 -> 195 | AD32: =+AC32*[1]Dublin!E34 -> 0 | AE32: 3 | AF32: =AE32*E32 -> 195 | AG32: 3 | AH32: =AG32*E32 -> 195 | AI32: 3 | AJ32: =AI32*E32 -> 195 | AK32: 3 | AL32: =AK32*E32 -> 195
A33: Pedestrian Logo's 980mm Yellow (Tesco) | B33: Kestrel | C33: Logo | D33: 1 Unit | E33: 15 | G33: 0 | H33: =+G33*E33 -> 0 | J33: =+I33*E33 -> 0 | K33: 0 | L33: =+K33*E33 -> 0 | N33: =+M33*E33 -> 0 | P33: =+O33*E33 -> 0 | R33: =+Q33*E33 -> 0 | S33: 0 | T33: =+S33*E33 -> 0 | V33: =+U33*E33 -> 0 | W33: 0 | X33: 0 | Z33: =+Y33*E33 -> 0 | AB33: =+AA33*E33 -> 0 | AD33: =+AC33*[1]Dublin!E35 -> 0 | AF33: =AE33*E33 -> 0 | AH33: =AG33*E33 -> 0 | AJ33: =AI33*E33 -> 0
A34: Celtic Knot logo | B34: Kestrel | C34: Logo | D34: 1 Unit | E34: 12 | G34: 2 | H34: =+G34*E34 -> 24 | I34: 2 | J34: =+I34*E34 -> 24 | K34: 0 | L34: =+K34*E34 -> 0 | M34: 0 | N34: =+M34*E34 -> 0 | P34: =+O34*E34 -> 0 | R34: =+Q34*E34 -> 0 | S34: 22 | T34: =+S34*E34 -> 264 | V34: =+U34*E34 -> 0 | W34: 0 | X34: 0 | Y34: 61 | Z34: =+Y34*E34 -> 732 | AA34: 16 | AB34: =+AA34*E34 -> 192 | AC34: 1 | AD34: =+AC34*[1]Dublin!E36 -> 12 | AE34: 1 | AF34: =AE34*E34 -> 12 | AG34: 1 | AH34: =AG34*E34 -> 12 | AI34: 1 | AJ34: =AI34*E34 -> 12 | AK34: 1 | AL34: =AK34*E34 -> 12
A35: Digits 1-9 | B35: Kestrel | C35: Logo | D35: 1 Unit | E35: 3.6 | P35: =+O35*E35 -> 0 | R35: =+Q35*E35 -> 0 | V35: =+U35*E35 -> 0 | Y35: =22+14+30+13+7+5+5+6+5+17 -> 124 | Z35: =+Y35*E35 -> 446.4 | AB35: =+AA35*E35 -> 0 | AD35: =+AC35*[1]Dublin!E37 -> 0 | AE35: 12 | AF35: =AE35*E35 -> 43.2 | AH35: =AG35*E35 -> 0 | AJ35: =AI35*E35 -> 0 | AK35: 10 | AL35: =AK35*E35 -> 36
A36: IDA Letters | B36: Kestrel | C36: Logo | D36: 1 Unit | E36: 3.75 | P36: =+O36*E36 -> 0 | R36: =+Q36*E36 -> 0 | V36: =+U36*E36 -> 0 | Y36: =3*20 -> 60 | Z36: =+Y36*E36 -> 225 | AB36: =+AA36*E36 -> 0 | AD36: =+AC36*[1]Dublin!E38 -> 0 | AF36: =AE36*E36 -> 0 | AH36: =AG36*E36 -> 0 | AJ36: =AI36*E36 -> 0
A37: Visitor letters | B37: Kestrel | C37: Logo | D37: 1 Unit | E37: 1.85 | P37: =+O37*E37 -> 0 | R37: =+Q37*E37 -> 0 | V37: =+U37*E37 -> 0 | Y37: =7*4 -> 28 | Z37: =+Y37*E37 -> 51.8 | AB37: =+AA37*E37 -> 0 | AD37: =+AC37*[1]Dublin!E39 -> 0 | AF37: =AE37*E37 -> 0 | AH37: =AG37*E37 -> 0 | AJ37: =AI37*E37 -> 0
A38: IDA Visitors 05/06/07 | B38: Kestrel | C38: Logo | D38: 1 Unit | E38: 82.5 | P38: =+O38*E38 -> 0 | R38: =+Q38*E38 -> 0 | V38: =+U38*E38 -> 0 | Y38: 3 | Z38: =+Y38*E38 -> 247.5 | AB38: =+AA38*E38 -> 0 | AD38: =+AC38*[1]Dublin!E40 -> 0 | AF38: =AE38*E38 -> 0 | AH38: =AG38*E38 -> 0 | AJ38: =AI38*E38 -> 0
A39: Electrical Vehicle only | B39: Kestrel | C39: Logo | D39: 1 Unit | E39: 4 | Y39: 300 | Z39: =+Y39*E39 -> 1200 | AB39: =+AA39*E39 -> 0 | AD39: =+AC39*[1]Dublin!E41 -> 0 | AE39: 360 | AF39: =AE39*E39 -> 1440 | AG39: 360 | AH39: =AG39*E39 -> 1440 | AI39: 360 | AJ39: =AI39*E39 -> 1440 | AK39: 360 | AL39: =AK39*E39 -> 1440
A40: Age Friendly Parking | B40: Kestrel | C40: Logo | D40: 1 Unit | E40: 4 | Y40: 46 | Z40: =+Y40*E40 -> 184 | AA40: 29 | AB40: =+AA40*E40 -> 116 | AD40: =+AC40*[1]Dublin!E42 -> 0 | AE40: 144 | AF40: =AE40*E40 -> 576 | AG40: 144 | AH40: =AG40*E40 -> 576 | AI40: 133 | AJ40: =AI40*E40 -> 532 | AK40: 133 | AL40: =AK40*E40 -> 532
...

Sheet Clonmel 
A1: Clonmel Yard Stock | F1: 45838 | J1: 45901 | L1: 45931 | N1: 45962 | P1: 45992 | R1: 45662 | T1: 46056 | V1: 46083 | X1: 46113 | Z1: 46143 | AB1: 46175 | AD1: 46203 | AF1: 31st July | AH1: 31st Aug
A2: Description | B2: Supplier | C2: Type | D2: Unit | E2: 2025 Prices | F2: Stock | G2: Value | H2: Stock | I2: Value | J2: Stock | K2: Value | L2: Stock | M2: Value | N2: Stock | O2: Value | Q2: Value | S2: Value | W2: Value | AE2: Value | AI2: Value
A3: White Extrusion 80/20 | B3: Kestrel | C3: Thermo-P | D3: Tonne | E3: 890 | F3: 1.5 | G3: =E3*F3 -> 1335 | H3: 1.5 | I3: 1335 | J3: 5 | K3: =SUM(J3*E3) -> 4450 | L3: 0 | M3: =L3*E3 -> 0 | N3: 2 | O3: =E3*N3 -> 1780 | P3: 15 | Q3: 13350 | R3: 5 | S3: =SUM(R3)*E3 -> 4450 | T3: 25 | U3: =SUM(T3*E3) -> 22250 | V3: 7 | W3: 6230 | X3: 13.5 | Y3: =SUM(X3*E3) -> 12015 | Z3: 0 | AA3: 0 | AB3: 12.5 | AC3: =SUM(AB3*E3) -> 11125 | AD3: 15.5 | AE3: =SUM(AD3*E3) -> 13795 | AF3: 15.463 | AG3: 13761.63 | AH3: ='Clonmel Trucks & Yard'!F3/1000 -> 227.6875 | AI3: =AH3*E3 -> 202641.88
A4: Yellow Extrusion 55/20 | B4: Kestrel | C4: Thermo-P | D4: Tonne | E4: 930 | F4: 14 | G4: =E4*F4 -> 13020 | H4: 6 | I4: 5580 | J4: 5 | K4: =SUM(J4*E4) -> 4650 | L4: 9 | M4: =L4*E4 -> 8370 | N4: 6 | O4: =E4*N4 -> 5580 | P4: 5 | Q4: 4650 | R4: 14 | S4: =SUM(R4)*E4 -> 13020 | T4: 16 | U4: =SUM(T4*E4) -> 14880 | V4: 13 | W4: 12090 | X4: 17 | Y4: =SUM(X4*E4) -> 15810 | Z4: 2 | AA4: 1860 | AB4: 8 | AC4: =SUM(AB4*E4) -> 7440 | AD4: 7 | AE4: =SUM(AD4*E4) -> 6510 | AF4: 13.289 | AG4: 12357.37 | AH4: ='Clonmel Trucks & Yard'!J3/1000 -> 115.2 | AI4: =AH4*E4 -> 107136
A5: White 70/0 Non Refl | B5: Kestrel | C5: Thermo-P | D5: Tonne | E5: 650 | G5: =E5*F5 -> 0 | H5: 0 | I5: 0 | J5: 0 | K5: =SUM(J5*E5) -> 0 | L5: 0 | M5: =L5*E5 -> 0 | O5: =E5*N5 -> 0 | P5: 0 | Q5: 0 | R5: 0 | S5: =SUM(R5)*E5 -> 0 | T5: 0 | U5: =SUM(T5*E5) -> 0 | V5: 0 | W5: 0 | X5: 0 | Y5: =SUM(X5*E5) -> 0 | Z5: 0 | AA5: 0 | AB5: 0 | AC5: =SUM(AB5*E5) -> 0 | AD5: 0 | AE5: =SUM(AD5*E5) -> 0 | AF5: 0 | AG5: 0 | AH5: 0 | AI5: =AH5*E5 -> 0
A6: White Ultralux 200 | B6: Kestrel | C6: Thermo-P | D6: Tonne | E6: 1210 | G6: =E6*F6 -> 0 | H6: 0 | I6: 0 | J6: 0 | K6: =SUM(J6*E6) -> 0 | L6: 0 | M6: =L6*E6 -> 0 | O6: =E6*N6 -> 0 | P6: 0 | Q6: 0 | R6: 0 | S6: =SUM(R6)*E6 -> 0 | T6: 2 | U6: =SUM(T6*E6) -> 2420 | V6: 2 | W6: 2420 | X6: 1 | Y6: =SUM(X6*E6) -> 1210 | Z6: 0 | AA6: 0 | AB6: 3 | AC6: =SUM(AB6*E6) -> 3630 | AD6: 2.5 | AE6: =SUM(AD6*E6) -> 3025 | AF6: 1 | AG6: 1210 | AH6: ='Clonmel Trucks & Yard'!M20/1000 -> 2 | AI6: =AH6*E6 -> 2420
A7: Yellow Ultralux 200 | B7: Kestrel | C7: Thermo-P | D7: Tonne | E7: 1245 | G7: =E7*F7 -> 0 | H7: 0 | I7: 0 | J7: 0 | K7: =SUM(J7*E7) -> 0 | L7: 0 | M7: =L7*E7 -> 0 | O7: =E7*N7 -> 0 | P7: 0 | Q7: 0 | R7: 0 | S7: =SUM(R7)*E7 -> 0 | T7: 0 | U7: =SUM(T7*E7) -> 0 | V7: 0 | W7: 0 | X7: 0 | Y7: =SUM(X7*E7) -> 0 | Z7: 0 | AA7: 0 | AB7: 0 | AC7: =SUM(AB7*E7) -> 0 | AD7: 0 | AE7: =SUM(AD7*E7) -> 0 | AG7: 0 | AI7: =AH7*E7 -> 0
A8: White Ribline Ultralux 200 | B8: Kestrel | C8: Thermo-P | D8: Tonne | E8: 1250 | G8: =E8*F8 -> 0 | H8: 0 | I8: 0 | J8: 0 | K8: =SUM(J8*E8) -> 0 | L8: 0 | M8: =L8*E8 -> 0 | O8: =E8*N8 -> 0 | P8: 0 | Q8: 0 | R8: 0 | S8: =SUM(R8)*E8 -> 0 | T8: 0 | U8: =SUM(T8*E8) -> 0 | V8: 0 | W8: 0 | X8: 0 | Y8: =SUM(X8*E8) -> 0 | Z8: 0 | AA8: 0 | AB8: 0 | AC8: =SUM(AB8*E8) -> 0 | AD8: 0 | AE8: =SUM(AD8*E8) -> 0 | AG8: 0 | AI8: =AH8*E8 -> 0
A9: White - Briteline | B9: Kelly | C9: Thermo-P | D9: Tonne | E9: 890 | F9: 15.25 | G9: =E9*F9 -> 13572.5 | H9: 24.5 | I9: 21805 | J9: 18 | K9: =SUM(J9*E9) -> 16020 | L9: 22 | M9: =L9*E9 -> 19580 | N9: 14.5 | O9: =E9*N9 -> 12905 | P9: 3 | Q9: 2670 | R9: 0 | S9: =SUM(R9)*E9 -> 0 | T9: 0 | U9: =SUM(T9*E9) -> 0 | V9: 0 | W9: 0 | X9: 0 | Y9: =SUM(X9*E9) -> 0 | Z9: 12.5 | AA9: 11125 | AB9: 13.5 | AC9: =SUM(AB9*E9) -> 12015 | AD9: 6 | AE9: =SUM(AD9*E9) -> 5340 | AF9: 1 | AG9: 890 | AH9: ='Clonmel Trucks & Yard'!M18/1000 -> 2.5 | AI9: =AH9*E9 -> 2225
A10: Yellow - Briteline | B10: Kelly | C10: Thermo-P | D10: Tonne | E10: 915 | F10: 17.75 | G10: =E10*F10 -> 16241.25 | H10: 24 | I10: 21960 | J10: 10.5 | K10: =SUM(J10*E10) -> 9607.5 | L10: 13.5 | M10: =L10*E10 -> 12352.5 | N10: 13.5 | O10: =E10*N10 -> 12352.5 | P10: 12 | Q10: 10980 | R10: 0 | S10: =SUM(R10)*E10 -> 0 | T10: 0 | U10: =SUM(T10*E10) -> 0 | V10: 0 | W10: 0 | X10: 0 | Y10: =SUM(X10*E10) -> 0 | Z10: 6 | AA10: 5490 | AB10: 9 | AC10: =SUM(AB10*E10) -> 8235 | AD10: 11.5 | AE10: =SUM(AD10*E10) -> 10522.5 | AF10: 1.5 | AG10: 1372.5 | AH10: ='Clonmel Trucks & Yard'!M19/1000 -> 2.5 | AI10: =AH10*E10 -> 2287.5
A11: White - Wetline | B11: Kelly | C11: Thermo-P | D11: Tonne | E11: 1495 | F11: 5 | G11: =E11*F11 -> 7475 | H11: 5 | I11: 7475 | J11: 5 | K11: =SUM(J11*E11) -> 7475 | L11: 5 | M11: =L11*E11 -> 7475 | N11: 5 | O11: =E11*N11 -> 7475 | P11: 5 | Q11: 7475 | R11: 5 | S11: =SUM(R11)*E11 -> 7475 | T11: 5 | U11: =SUM(T11*E11) -> 7475 | V11: 5 | W11: 7475 | X11: 4.5 | Y11: =SUM(X11*E11) -> 6727.5 | Z11: 4.5 | AA11: 6727.5 | AB11: 1.5 | AC11: =SUM(AB11*E11) -> 2242.5 | AD11: 2 | AE11: =SUM(AD11*E11) -> 2990 | AF11: 1 | AG11: 1495 | AI11: =AH11*E11 -> 0
A12: Yellow Briteline + | B12: Kelly | C12: Thermo-P | D12: Tonne | E12: 1185 | F12: 3 | G12: =E12*F12 -> 3555 | H12: 2 | I12: 2370 | J12: 2 | K12: =SUM(J12*E12) -> 2370 | L12: 4 | M12: =L12*E12 -> 4740 | N12: 4 | O12: =E12*N12 -> 4740 | P12: 3.25 | Q12: 3851.25 | R12: 3.25 | S12: =SUM(R12)*E12 -> 3851.25 | T12: 3 | U12: =SUM(T12*E12) -> 3555 | V12: 3 | W12: 3555 | X12: 3 | Y12: =SUM(X12*E12) -> 3555 | Z12: 4 | AA12: 4740 | AB12: 3.25 | AC12: =SUM(AB12*E12) -> 3851.25 | AD12: 3.25 | AE12: =SUM(AD12*E12) -> 3851.25 | AF12: 1.15 | AG12: 1362.75 | AI12: =AH12*E12 -> 0
A13: White Briteline + | B13: Kelly | C13: Thermo-P | D13: Tonne | E13: 1185 | F13: 3.5 | G13: =E13*F13 -> 4147.5 | H13: 3 | I13: 3555 | J13: 6 | K13: =SUM(J13*E13) -> 7110 | L13: 3 | M13: =L13*E13 -> 3555 | N13: 3 | O13: =E13*N13 -> 3555 | P13: 1.8 | Q13: 2133 | R13: 1.8 | S13: =SUM(R13)*E13 -> 2133 | T13: 0 | U13: =SUM(T13*E13) -> 0 | V13: 0 | W13: 0 | X13: 1.5 | Y13: =SUM(X13*E13) -> 1777.5 | Z13: 3.5 | AA13: 4147.5 | AB13: 1 | AC13: =SUM(AB13*E13) -> 1185 | AD13: 4.5 | AE13: =SUM(AD13*E13) -> 5332.5 | AF13: 1.15 | AG13: 1362.75 | AI13: =AH13*E13 -> 0
A14: Swarco Beads High Grade | B14: Kestrel | C14: Beads | D14: Tonne | E14: 1390 | F14: 0.3 | G14: =E14*F14 -> 417 | H14: 1.1 | I14: 1648.9 | J14: 2.1 | K14: =SUM(J14*E14) -> 2919 | L14: 1.8 | M14: =L14*E14 -> 2502 | N14: 1.4 | O14: =E14*N14 -> 1946 | P14: 1 | Q14: 1499 | R14: 1 | S14: =SUM(R14)*E14 -> 1390 | T14: 1 | U14: =SUM(T14*E14) -> 1390 | V14: 1 | W14: 1499 | X14: 0.6 | Y14: =SUM(X14*E14) -> 834 | Z14: 0.25 | AA14: 374.75 | AB14: 0.6 | AC14: =SUM(AB14*E14) -> 834 | AD14: 0.5 | AE14: =SUM(AD14*E14) -> 695 | AF14: 0.2 | AG14: 278 | AI14: =AH14*E14 -> 0
A15: Beads | B15: Kestrel | C15: Beads | D15: Tonne | E15: 790 | F15: 2 | G15: =E15*F15 -> 1580 | H15: 2.2 | I15: 1980 | J15: 2 | K15: =SUM(J15*E15) -> 1580 | L15: 1.5 | M15: =L15*E15 -> 1185 | N15: 2 | O15: =E15*N15 -> 1580 | P15: 2 | Q15: 1800 | R15: 1.8 | S15: =SUM(R15)*E15 -> 1422 | T15: 2 | U15: =SUM(T15*E15) -> 1580 | V15: 2 | W15: 1800 | X15: 1 | Y15: =SUM(X15*E15) -> 790 | Z15: 1 | AA15: 900 | AB15: 2.25 | AC15: =SUM(AB15*E15) -> 1777.5 | AD15: 2 | AE15: =SUM(AD15*E15) -> 1580 | AF15: 0.6 | AG15: 474 | AH15: =+'Clonmel Trucks & Yard'!M3/1000 -> 2 | AI15: =AH15*E15 -> 1580
A16: Bitumen / Stud Grout | B16: Kestrel | C16: C-E | D16: Tonne | E16: 755 | F16: 2.2 | G16: =E16*F16 -> 1661 | H16: 1.25 | I16: 793.75 | J16: 1 | K16: =SUM(J16*E16) -> 755 | L16: 2.5 | M16: =L16*E16 -> 1887.5 | N16: 2.4 | O16: =E16*N16 -> 1812 | P16: 1.2 | Q16: 762 | R16: 1.2 | S16: =SUM(R16)*E16 -> 906 | T16: 0.75 | U16: =SUM(T16*E16) -> 566.25 | V16: 0.25 | W16: 158.75 | X16: 0.25 | Y16: =SUM(X16*E16) -> 188.75 | Z16: 0.25 | AA16: 158.75 | AB16: 0 | AC16: =SUM(AB16*E16) -> 0 | AD16: 0 | AE16: =SUM(AD16*E16) -> 0 | AF16: 0 | AG16: 0 | AI16: =AH16*E16 -> 0
A17: Polymer Modified Bitumen | B17: Kestrel | C17: C-E | D17: Tonne | E17: 665 | F17: 2 | G17: =E17*F17 -> 1330 | H17: 2 | I17: 1330 | J17: 2 | K17: =SUM(J17*E17) -> 1330 | L17: 1.1 | M17: =L17*E17 -> 731.5 | N17: 0.75 | O17: =E17*N17 -> 498.75 | P17: 1 | Q17: 665 | R17: 0 | S17: =SUM(R17)*E17 -> 0 | T17: 0 | U17: =SUM(T17*E17) -> 0 | V17: 2 | W17: 1330 | X17: 1 | Y17: =SUM(X17*E17) -> 665 | Z17: 2.25 | AA17: 1496.25 | AB17: 0.5 | AC17: =SUM(AB17*E17) -> 332.5 | AD17: 2.25 | AE17: =SUM(AD17*E17) -> 1496.25 | AF17: 2.15 | AG17: 1429.75 | AI17: =AH17*E17 -> 0
A18: Joint Sealer Bitumen | B18: Ennis Flint | C18: C-E | D18: Tonne | E18: 850 | G18: =E18*F18 -> 0 | H18: 0 | I18: 0 | J18: 0 | K18: =SUM(J18*E18) -> 0 | L18: 0 | M18: =L18*E18 -> 0 | N18: 0 | O18: =E18*N18 -> 0 | Q18: 0 | R18: 0 | S18: =SUM(R18)*E18 -> 0 | T18: 0 | U18: =SUM(T18*E18) -> 0 | V18: 0 | W18: 0 | X18: 0 | Y18: =SUM(X18*E18) -> 0 | Z18: 0 | AA18: 0 | AB18: 0 | AC18: =SUM(AB18*E18) -> 0 | AD18: 0 | AE18: =SUM(AD18*E18) -> 0 | AF18: 0 | AG18: 0 | AI18: =AH18*E18 -> 0
A19: Cast Iron Studs | B19: Roadstuds | C19: C-E | D19: I Unit | E19: =5.2/0.85 -> 6.1176471 | F19: 1288 | G19: =E19*F19 -> 7879.5294 | H19: 1040 | I19: 6362.3529 | J19: 800 | K19: =SUM(J19*E19) -> 4894.1176 | L19: 390 | M19: =L19*E19 -> 2385.8824 | N19: 350 | O19: =E19*N19 -> 2141.1765 | P19: 350 | Q19: 2141.1765 | R19: 350 | S19: =SUM(R19)*E19 -> 2141.1765 | T19: 160 | U19: =SUM(T19*E19) -> 978.82353 | V19: 160 | W19: 978.82353 | X19: 160 | Y19: =SUM(X19*E19) -> 978.82353 | Z19: 160 | AA19: 978.82353 | AB19: 160 | AC19: =SUM(AB19*E19) -> 978.82353 | AD19: 220 | AE19: =SUM(AD19*E19) -> 1345.8824 | AF19: 220 | AG19: 1345.8824 | AI19: =AH19*E19 -> 0
A20: Catseye Pads | B20: Roadstuds | C20: C-E | D20: I Unit | E20: =2.45/0.85 -> 2.8823529 | F20: 1250 | G20: =E20*F20 -> 3602.9412 | H20: 1000 | I20: 2882.3529 | J20: 750 | K20: =SUM(J20*E20) -> 2161.7647 | L20: 500 | M20: =L20*E20 -> 1441.1765 | N20: 500 | O20: =E20*N20 -> 1441.1765 | P20: 500 | Q20: 1441.1765 | R20: 500 | S20: =SUM(R20)*E20 -> 1441.1765 | T20: 400 | U20: =SUM(T20*E20) -> 1152.9412 | V20: 400 | W20: 1152.9412 | X20: 500 | Y20: =SUM(X20*E20) -> 1441.1765 | Z20: 500 | AA20: 1441.1765 | AB20: 500 | AC20: =SUM(AB20*E20) -> 1441.1765 | AD20: 500 | AE20: =SUM(AD20*E20) -> 1441.1765 | AF20: 500 | AG20: 1441.1765 | AI20: =AH20*E20 -> 0
A21: Road Studs 301 Type | B21: Roadcraft | C21: C-E | D21: 1 Unit | E21: =5.89/0.85 -> 6.9294118 | F21: 2971 | G21: =E21*F21 -> 20587.282 | H21: 2971 | I21: 20587.282 | J21: 2971 | K21: =SUM(J21*E21) -> 20587.282 | L21: 1160 | M21: =L21*E21 -> 8038.1176 | N21: 3100 | O21: =E21*N21 -> 21481.176 | P21: 3120 | Q21: 21619.765 | R21: 2280 | S21: =SUM(R21)*E21 -> 15799.059 | T21: 2040 | U21: =SUM(T21*E21) -> 14136 | V21: 5040 | W21: 34924.235 | X21: 4103 | Y21: =SUM(X21*E21) -> 28431.376 | Z21: 3365 | AA21: 23317.471 | AB21: 2310 | AC21: =SUM(AB21*E21) -> 16006.941 | AD21: 2285 | AE21: =SUM(AD21*E21) -> 15833.706 | AF21: 1520 | AG21: 10532.706 | AI21: =AH21*E21 -> 0
A22: Stick On Studs - Meon | B22: Meon | C22: C-E | D22: I Unit | E22: 1.45 | F22: 2850 | G22: =E22*F22 -> 4132.5 | H22: 2850 | I22: 4132.5 | J22: 2850 | K22: =SUM(J22*E22) -> 4132.5 | L22: 2850 | M22: =L22*E22 -> 4132.5 | N22: 2800 | O22: =E22*N22 -> 4060 | P22: 2800 | Q22: 4060 | R22: 2800 | S22: =SUM(R22)*E22 -> 4060 | T22: 2800 | U22: =SUM(T22*E22) -> 4060 | V22: 2800 | W22: 4060 | X22: 2800 | Y22: =SUM(X22*E22) -> 4060 | Z22: 2800 | AA22: 4060 | AB22: 2800 | AC22: =SUM(AB22*E22) -> 4060 | AD22: 2500 | AE22: =SUM(AD22*E22) -> 3625 | AF22: 2500 | AG22: 3625 | AI22: =AH22*E22 -> 0
A23: Stick On Studs - Roadcraft 1st July | B23: Roadcraft | C23: C-E | D23: 1 Unit | E23: =1.4/0.9 -> 1.5555556 | G23: =E23*F23 -> 0 | I23: 0 | K23: =SUM(J23*E23) -> 0 | M23: =L23*E23 -> 0 | N23: 0 | O23: =E23*N23 -> 0 | P23: 0 | Q23: 0 | R23: 0 | S23: =SUM(R23)*E23 -> 0 | T23: 0 | U23: =SUM(T23*E23) -> 0 | V23: 0 | W23: 0 | X23: 0 | Y23: =SUM(X23*E23) -> 0 | Z23: 0 | AA23: 0 | AB23: 0 | AC23: =SUM(AB23*E23) -> 0 | AD23: 0 | AE23: =SUM(AD23*E23) -> 0 | AF23: 0 | AG23: 0 | AI23: =AH23*E23 -> 0
A24: Anti Skid Buff - Kelly's | B24: Kelly | C24: A-S | D24: Tonne | E24: 1100 | F24: 6.5 | G24: =E24*F24 -> 7150 | H24: 8 | I24: 8800 | J24: 9.5 | K24: =SUM(J24*E24) -> 10450 | L24: 6.1 | M24: =L24*E24 -> 6710 | N24: 4 | O24: =E24*N24 -> 4400 | P24: 10.25 | Q24: 11275 | R24: 9 | S24: =SUM(R24)*E24 -> 9900 | T24: 9 | U24: =SUM(T24*E24) -> 9900 | V24: 4.5 | W24: 4950 | X24: 0 | Y24: =SUM(X24*E24) -> 0 | Z24: 0 | AA24: 0 | AB24: 0 | AC24: =SUM(AB24*E24) -> 0 | AD24: 0 | AE24: =SUM(AD24*E24) -> 0 | AF24: 0 | AG24: 0 | AH24: =+('Clonmel Trucks & Yard'!M16+'Clonmel Trucks & Yard'!G41)/1000 -> 64.0625 | AI24: =AH24*E24 -> 70468.75
A25: Anti Skid Red | B25: Kelly | C25: A-S | D25: Tonne | E25: 833 | F25: 5.5 | G25: =E25*F25 -> 4581.5 | H25: 7.5 | I25: 6247.5 | J25: 9.4 | K25: =SUM(J25*E25) -> 7830.2 | L25: 9.5 | M25: =L25*E25 -> 7913.5 | N25: 6 | O25: =E25*N25 -> 4998 | P25: 4 | Q25: 3332 | R25: 3 | S25: =SUM(R25)*E25 -> 2499 | T25: 0 | U25: =SUM(T25*E25) -> 0 | V25: 0 | W25: 0 | X25: 1.5 | Y25: =SUM(X25*E25) -> 1249.5 | Z25: 4.5 | AA25: 3748.5 | AB25: 8 | AC25: =SUM(AB25*E25) -> 6664 | AD25: 6 | AE25: =SUM(AD25*E25) -> 4998 | AF25: 0 | AG25: 0 | AH25: =+('Clonmel Trucks & Yard'!M17+'Clonmel Trucks & Yard'!G42)/1000 -> 76.5625 | AI25: =AH25*E25 -> 63776.562
A26: Buff - Type 1 KestrelGrip ( 1.250 Kg) | B26: Kestrel | C26: A-S | D26: Tonne | E26: 1125 | F26: 3 | G26: =E26*F26 -> 3375 | H26: 0 | I26: 0 | J26: 0 | K26: =SUM(J26*E26) -> 0 | L26: 0 | M26: =L26*E26 -> 0 | N26: 0 | O26: =E26*N26 -> 0 | Q26: 0 | R26: 0.5 | S26: =SUM(R26)*E26 -> 562.5 | T26: 0 | U26: =SUM(T26*E26) -> 0 | V26: 0 | W26: 0 | X26: 7.25 | Y26: =SUM(X26*E26) -> 8156.25 | Z26: 6 | AA26: 6750 | AB26: 10 | AC26: =SUM(AB26*E26) -> 11250 | AD26: 0 | AE26: =SUM(AD26*E26) -> 0 | AF26: 13.5 | AG26: 14850 | AI26: =AH26*E26 -> 0
A27: Red - KestrelFlex - Anti-Skid | B27: Kestrel | C27: A-S | D27: Tonne | E27: 885 | G27: =E27*F27 -> 0 | H27: 0 | I27: 0 | J27: 0 | K27: =SUM(J27*E27) -> 0 | L27: 0 | M27: =L27*E27 -> 0 | N27: 0 | O27: =E27*N27 -> 0 | P27: 6 | Q27: 5310 | R27: 5.25 | S27: =SUM(R27)*E27 -> 4646.25 | T27: 5.25 | U27: =SUM(T27*E27) -> 4646.25 | V27: 3.5 | W27: 3097.5 | X27: 5 | Y27: =SUM(X27*E27) -> 4425 | Z27: 0 | AA27: 0 | AB27: 0 | AC27: =SUM(AB27*E27) -> 0 | AD27: 2 | AE27: =SUM(AD27*E27) -> 1770 | AF27: 5 | AG27: 4165 | AI27: =AH27*E27 -> 0
A28: Anti Skid Grains (€550 p/T) | B28: Kestrel | C28: A-S | D28: 14kg | E28: 14 | F28: 10 | G28: =E28*F28 -> 140 | H28: 10 | I28: 140 | J28: 9 | K28: =SUM(J28*E28) -> 126 | L28: 9 | M28: =L28*E28 -> 126 | N28: 9 | O28: =E28*N28 -> 126 | P28: 8 | Q28: 126 | R28: 8 | S28: =SUM(R28)*E28 -> 112 | T28: 7 | U28: =SUM(T28*E28) -> 98 | V28: 7 | W28: 98 | X28: 6 | Y28: =SUM(X28*E28) -> 84 | Z28: 10 | AA28: 140 | AB28: 9 | AC28: =SUM(AB28*E28) -> 126 | AD28: 8 | AE28: =SUM(AD28*E28) -> 112 | AF28: 4 | AG28: 56 | AI28: =AH28*E28 -> 0
A29: Meon Uniprime X250 Concrete Primer | B29: Meon | C29: Primer | D29: 25L | E29: 311.43 | G29: =E29*F29 -> 0 | H29: 0 | I29: 0 | K29: =SUM(J29*E29) -> 0 | L29: 0 | M29: =L29*E29 -> 0 | N29: 0 | O29: =E29*N29 -> 0 | P29: 0 | Q29: 0 | R29: 0 | S29: =SUM(R29)*E29 -> 0 | T29: 0 | U29: =SUM(T29*E29) -> 0 | V29: 0 | W29: 0 | X29: 0 | Y29: =SUM(X29*E29) -> 0 | Z29: 0 | AA29: 0 | AB29: 0 | AC29: =SUM(AB29*E29) -> 0 | AD29: 0 | AE29: =SUM(AD29*E29) -> 0 | AG29: 0 | AI29: =AH29*E29 -> 0
A30: Meon Uniprime X450 Concrete Primer w. Thermo | B30: Meon | C30: Primer | D30: 14kg | E30: 150.6 | G30: =E30*F30 -> 0 | H30: 0 | I30: 0 | K30: =SUM(J30*E30) -> 0 | L30: 0 | M30: =L30*E30 -> 0 | N30: 0 | O30: =E30*N30 -> 0 | P30: 0 | Q30: 0 | R30: 0 | S30: =SUM(R30)*E30 -> 0 | T30: 0 | U30: =SUM(T30*E30) -> 0 | V30: 0 | W30: 0 | X30: 0 | Y30: =SUM(X30*E30) -> 0 | Z30: 0 | AA30: 0 | AB30: 0 | AC30: =SUM(AB30*E30) -> 0 | AD30: 0 | AE30: =SUM(AD30*E30) -> 0 | AG30: 0 | AI30: =AH30*E30 -> 0
A31: Pink Tacoat-Primer - Tins | B31: Kellys | C31: Primer | D31: 25L | E31: 230 | G31: =E31*F31 -> 0 | H31: 0 | I31: 0 | K31: =SUM(J31*E31) -> 0 | L31: 4 | M31: =L31*E31 -> 920 | N31: 2 | O31: =E31*N31 -> 460 | P31: 0 | Q31: 0 | R31: 0 | S31: =SUM(R31)*E31 -> 0 | T31: 0 | U31: =SUM(T31*E31) -> 0 | V31: 0 | W31: 0 | X31: 0 | Y31: =SUM(X31*E31) -> 0 | Z31: 0 | AA31: 0 | AB31: 0 | AC31: =SUM(AB31*E31) -> 0 | AD31: 4 | AE31: =SUM(AD31*E31) -> 920 | AG31: 0 | AI31: =AH31*E31 -> 0
A32: Visever IBC'S Units | B32: Visever | C32: Primer | D32: 900kg | E32: 3.1 | F32: 1650 | G32: =E32*F32 -> 5115 | H32: 1350 | I32: 4185 | J32: 1250 | K32: =SUM(J32*E32) -> 3875 | L32: 1000 | M32: =L32*E32 -> 3100 | N32: 950 | O32: =E32*N32 -> 2945 | P32: 800 | Q32: 2480 | R32: 800 | S32: =SUM(R32)*E32 -> 2480 | T32: 750 | U32: =SUM(T32*E32) -> 2325 | V32: 550 | W32: 1705 | X32: 300 | Y32: =SUM(X32*E32) -> 930 | Z32: 0 | AA32: 0 | AB32: 900 | AC32: =SUM(AB32*E32) -> 2790 | AD32: 1600 | AE32: =SUM(AD32*E32) -> 4960 | AF32: 300 | AG32: 930 | AI32: =AH32*E32 -> 0
A33: MultiGrip X440 Stong Blue | B33: Meon | C33: M-Grip | D33: 20 Kg | E33: 121.3 | F33: 18 | G33: =E33*F33 -> 2183.4 | H33: 26 | I33: 2990 | J33: 20 | K33: =SUM(J33*E33) -> 2426 | L33: 8 | M33: =L33*E33 -> 970.4 | N33: 16 | O33: =E33*N33 -> 1940.8 | P33: 12 | Q33: 1380 | R33: 12 | S33: =SUM(R33)*E33 -> 1455.6 | T33: 13 | U33: =SUM(T33*E33) -> 1576.9 | V33: 26 | W33: 2990 | X33: 13 | Y33: =SUM(X33*E33) -> 1576.9 | Z33: 28 | AA33: 3220 | AB33: 6 | AC33: =SUM(AB33*E33) -> 727.8 | AD33: 25 | AE33: =SUM(AD33*E33) -> 3032.5 | AF33: 12 | AG33: 1455.6 | AI33: =AH33*E33 -> 0
A34: MultiGrip X440 Yellow | B34: Meon | C34: M-Grip | D34: 20kg | E34: 139.9 | G34: =E34*F34 -> 0 | H34: 0 | I34: 0 | J34: 0 | K34: =SUM(J34*E34) -> 0 | L34: 0 | M34: =L34*E34 -> 0 | N34: 0 | O34: =E34*N34 -> 0 | P34: 0 | Q34: 0 | S34: =SUM(R34)*E34 -> 0 | T34: 0 | U34: =SUM(T34*E34) -> 0 | V34: 0 | W34: 0 | X34: 3 | Y34: =SUM(X34*E34) -> 419.7 | Z34: 3 | AA34: 419.7 | AB34: 1 | AC34: =SUM(AB34*E34) -> 139.9 | AD34: 2 | AE34: =SUM(AD34*E34) -> 279.8 | AF34: 0 | AG34: 0 | AI34: =AH34*E34 -> 0
A35: MultiGrip X440 Traffic Purple. RAL 4006 | B35: Meon | C35: M-Grip | D35: 20kg | E35: 145.21 | G35: =E35*F35 -> 0 | H35: 0 | I35: 0 | J35: 0 | K35: =SUM(J35*E35) -> 0 | L35: 0 | M35: =L35*E35 -> 0 | N35: 0 | O35: =E35*N35 -> 0 | P35: 0 | Q35: 0 | S35: =SUM(R35)*E35 -> 0 | T35: 0 | U35: =SUM(T35*E35) -> 0 | V35: 0 | W35: 0 | X35: 0 | Y35: =SUM(X35*E35) -> 0 | Z35: 0 | AA35: 0 | AB35: 0 | AC35: =SUM(AB35*E35) -> 0 | AD35: 0 | AE35: =SUM(AD35*E35) -> 0 | AF35: 0 | AG35: 0 | AI35: =AH35*E35 -> 0
A36: MultiGrip X440 Traffic Green RAL6024 | B36: Meon | C36: M-Grip | D36: 20kg | E36: 121.33 | F36: 9 | G36: =E36*F36 -> 1091.97 | H36: 7 | I36: 805 | J36: 11 | K36: =SUM(J36*E36) -> 1334.63 | L36: 5 | M36: =L36*E36 -> 606.65 | N36: 10 | O36: =E36*N36 -> 1213.3 | P36: 7 | Q36: 805 | R36: 8 | S36: =SUM(R36)*E36 -> 970.64 | T36: 10 | U36: =SUM(T36*E36) -> 1213.3 | V36: 8 | W36: 920 | X36: 8 | Y36: =SUM(X36*E36) -> 970.64 | Z36: 10 | AA36: 1150 | AB36: 16 | AC36: =SUM(AB36*E36) -> 1941.28 | AD36: 16.5 | AE36: =SUM(AD36*E36) -> 2001.945 | AF36: 10 | AG36: 1213.3 | AI36: =AH36*E36 -> 0
A37: Multigrip Bold red | B37: Meon | C37: M-Grip | D37: 20kg | E37: 127 | F37: 3 | G37: =E37*F37 -> 381 | H37: 7 | I37: 889 | J37: 1 | K37: =SUM(J37*E37) -> 127 | L37: 1 | M37: =L37*E37 -> 127 | N37: 1 | O37: =E37*N37 -> 127 | P37: 1 | Q37: 0 | R37: 1 | S37: =SUM(R37)*E37 -> 127 | T37: 1 | U37: =SUM(T37*E37) -> 127 | V37: 1 | W37: 127 | X37: 15 | Y37: =SUM(X37*E37) -> 1905 | Z37: 1 | AA37: 127 | AB37: 0 | AC37: =SUM(AB37*E37) -> 0 | AD37: 0 | AE37: =SUM(AD37*E37) -> 0 | AF37: 0 | AG37: 0 | AI37: =AH37*E37 -> 0
A38: Red Vialine - Ral 3004 | B38: Meon | C38: Vialine | D38: 20kg | E38: 253 | G38: =E38*F38 -> 0 | H38: 0 | I38: 0 | K38: =SUM(J38*E38) -> 0 | L38: 0 | M38: =L38*E38 -> 0 | O38: =E38*N38 -> 0 | P38: 0 | Q38: 0 | S38: =SUM(R38)*E38 -> 0 | T38: 0 | U38: =SUM(T38*E38) -> 0 | V38: 0 | W38: 0 | X38: 0 | Y38: =SUM(X38*E38) -> 0 | Z38: 0 | AA38: 0 | AB38: 0 | AC38: =SUM(AB38*E38) -> 0 | AD38: 2 | AE38: =SUM(AD38*E38) -> 506 | AF38: 0 | AG38: 0 | AI38: =AH38*E38 -> 0
A39: ViaLine White | B39: Meon | C39: Vialine | D39: 20kg | E39: 156.26 | F39: 9 | G39: =E39*F39 -> 1406.34 | H39: 8 | I39: 1108.08 | J39: 8 | K39: =SUM(J39*E39) -> 1250.08 | L39: 7 | M39: =L39*E39 -> 1093.82 | N39: 8 | O39: =E39*N39 -> 1250.08 | P39: 7 | Q39: 969.57 | R39: 7 | S39: =SUM(R39)*E39 -> 1093.82 | T39: 6 | U39: =SUM(T39*E39) -> 937.56 | V39: 7 | W39: 969.57 | X39: 4 | Y39: =SUM(X39*E39) -> 625.04 | Z39: 4 | AA39: 554.04 | AB39: 4 | AC39: =SUM(AB39*E39) -> 625.04 | AD39: 8 | AE39: =SUM(AD39*E39) -> 1250.08 | AF39: 10 | AG39: 1562.6 | AI39: =AH39*E39 -> 0
A40: ViaLine Black | B40: Meon | C40: Vialine | D40: 20kg | E40: 138.51 | F40: 11 | G40: =E40*F40 -> 1523.61 | H40: 10.5 | I40: 1454.355 | J40: 4 | K40: =SUM(J40*E40) -> 554.04 | L40: 2 | M40: =L40*E40 -> 277.02 | N40: 0 | O40: =E40*N40 -> 0 | P40: 0 | Q40: 0 | S40: =SUM(R40)*E40 -> 0 | T40: 0 | U40: =SUM(T40*E40) -> 0 | V40: 0 | W40: 0 | X40: 4 | Y40: =SUM(X40*E40) -> 554.04 | Z40: 4 | AA40: 554.04 | AB40: 3 | AC40: =SUM(AB40*E40) -> 415.53 | AD40: 1 | AE40: =SUM(AD40*E40) -> 138.51 | AF40: 1 | AG40: 138.51 | AI40: =AH40*E40 -> 0
...

Sheet Clonmel Trucks & Yard
C1: White Thermo | G1: Yellow Thermo | K1: Beads
C2: Pallets | D2: Bags | E2: Boiler | F2: Total | G2: Pallets | H2: Bags | I2: Boiler | J2: Total | K2: Pallets kgs | L2: Bags Kgs | M2: Total
C3: =M14 -> 150000 | D3: =+E38 -> 2500 | E3: =E23 -> 187.5 | F3: =(C3*1.5)+(D3)+E3 -> 227687.5 | G3: =M15 -> 75000 | H3: =+H38 -> 2500 | I3: =H23 -> 200 | J3: =(G3*1.5)+(H3)+I3 -> 115200 | L3: =+K38 -> 2000 | M3: =K3+L3 -> 2000
A5: Full Hand Truck Boiler = 10 bags or 250 Kgs
C6: White | F6: Yellow
A7: Boilers | C7: % Full | D7: KG per Full Boiler | E7: Kgs | F7: % Full | G7: KG per Full Boiler | H7: KGs
A8: 06 TN 3308 | B8: Feeder T | D8: 250 | E8: =+C8*D8 -> 0 | G8: 250 | H8: =+F8*G8 -> 0
A9: 06 TS 8391 | B9: Feeder T | C9: 0.75 | D9: 250 | E9: =+C9*D9 -> 187.5 | G9: 250 | H9: =+F9*G9 -> 0
A10: 262 D 1654 | B10: Feeder T | D10: 250 | E10: =+C10*D10 -> 0 | G10: 250 | H10: =+F10*G10 -> 0
A11: 05 TS 8347 | B11: Extruder | D11: 250 | E11: =+C11*D11 -> 0 | F11: 0.8 | G11: 250 | H11: =+F11*G11 -> 200
A12: 06 TN 3378 | B12: Extruder | D12: 250 | E12: =+C12*D12 -> 0 | G12: 250 | H12: =+F12*G12 -> 0 | J12: Yard
A13: 252 D 26246 | B13: Extruder | D13: 250 | E13: =+C13*D13 -> 0 | G13: 250 | H13: =+F13*G13 -> 0 | J13: Type | K13: Bags | L13: Kg Per Bag | M13: Kgs
A14: 07 TN 3217 | B14: Spare | D14: 250 | E14: =+C14*D14 -> 0 | G14: 250 | H14: =+F14*G14 -> 0 | J14: White | K14: 6000 | L14: 25 | M14: =+K14*L14 -> 150000
A15: 132 D 23815 | B15: ToD | D15: 250 | E15: =+C15*D15 -> 0 | G15: 250 | H15: =+F15*G15 -> 0 | J15: Yellow | K15: 3000 | L15: 25 | M15: =+K15*L15 -> 75000
A16: 132 TS 1108 | B16: KoD | D16: 250 | E16: =+C16*D16 -> 0 | G16: 250 | H16: =+F16*G16 -> 0 | J16: Buff | K16: 2500 | L16: 25 | M16: =+K16*L16 -> 62500
A17: 141 D 41062 | B17: LK | D17: 250 | E17: =+C17*D17 -> 0 | G17: 250 | H17: =+F17*G17 -> 0 | J17: Red | K17: 3000 | L17: 25 | M17: =+K17*L17 -> 75000
A18: 192 D 22122 | B18: JB | D18: 250 | E18: =+C18*D18 -> 0 | G18: 250 | H18: =+F18*G18 -> 0 | J18: Hi-Grade W | K18: 100 | L18: 25 | M18: =+K18*L18 -> 2500
A19: 201 D 6447 | B19: KoS | D19: 250 | E19: =+C19*D19 -> 0 | G19: 250 | H19: =+F19*G19 -> 0 | J19: Hi-Grade Y | K19: 100 | L19: 25 | M19: =+K19*L19 -> 2500
A20: 212 D 22432 | B20: PH | D20: 250 | E20: =+C20*D20 -> 0 | G20: 250 | H20: =+F20*G20 -> 0 | J20: Hi-Grade W (Kestrel) | K20: 100 | L20: 20 | M20: =+K20*L20 -> 2000
A21: 221 D 4378 | B21: GS | D21: 250 | E21: =+C21*D21 -> 0 | G21: 250 | H21: =+F21*G21 -> 0
A22: 251 D 23451 | B22: MoG | D22: 250 | E22: =+C22*D22 -> 0 | G22: 250 | H22: =+F22*G22 -> 0
B23: Total | E23: =SUM(E8:E22) -> 187.5 | H23: =SUM(H8:H22) -> 200
A25: Bags | C25: White | D25: KG per Bag | E25: Kgs | F25: Yellow | G25: KG per Bag | H25: Kgs | I25: Beads | J25: KG per Bag | K25: Kgs
A26: 06 TS 3308 | B26: Feeder T | D26: 25 | E26: =+C26*D26 -> 0 | G26: 25 | H26: =+F26*G26 -> 0 | J26: 20 | K26: =+I26*J26 -> 0
A27: 06 TS 8391 | B27: Feeder T | D27: 25 | E27: =+C27*D27 -> 0 | G27: 25 | H27: =+F27*G27 -> 0 | J27: 20 | K27: =+I27*J27 -> 0
A28: 262 D 1654 | B28: Feeder T | D28: 25 | E28: =+C28*D28 -> 0 | G28: 25 | H28: =+F28*G28 -> 0 | J28: 20 | K28: =+I28*J28 -> 0
A29: 07 TN 3217 | B29: Spare | C29: 100 | D29: 25 | E29: =+C29*D29 -> 2500 | G29: 25 | H29: =+F29*G29 -> 0 | J29: 20 | K29: =+I29*J29 -> 0
A30: 132 D 23815 | B30: ToD | D30: 25 | E30: =+C30*D30 -> 0 | G30: 25 | H30: =+F30*G30 -> 0 | J30: 20 | K30: =+I30*J30 -> 0
A31: 132 TS 1108 | B31: KoD | D31: 25 | E31: =+C31*D31 -> 0 | G31: 25 | H31: =+F31*G31 -> 0 | J31: 20 | K31: =+I31*J31 -> 0
A32: 141 D 41062 | B32: LK | D32: 25 | E32: =+C32*D32 -> 0 | F32: 100 | G32: 25 | H32: =+F32*G32 -> 2500 | J32: 20 | K32: =+I32*J32 -> 0
A33: 192 D 22122 | B33: JB | D33: 25 | E33: =+C33*D33 -> 0 | G33: 25 | H33: =+F33*G33 -> 0 | I33: 100 | J33: 20 | K33: =+I33*J33 -> 2000
A34: 201 D 6447 | B34: KoS | D34: 25 | E34: =+C34*D34 -> 0 | G34: 25 | H34: =+F34*G34 -> 0 | J34: 20 | K34: =+I34*J34 -> 0
A35: 212 D 22432 | B35: PH | D35: 25 | E35: =+C35*D35 -> 0 | G35: 25 | H35: =+F35*G35 -> 0 | J35: 20 | K35: =+I35*J35 -> 0
A36: 221 D 4378 | B36: GS | D36: 25 | E36: =+C36*D36 -> 0 | G36: 25 | H36: =+F36*G36 -> 0 | J36: 20 | K36: =+I36*J36 -> 0
A37: 251 D 23451 | B37: MoG | D37: 25 | E37: =+C37*D37 -> 0 | G37: 25 | H37: =+F37*G37 -> 0 | J37: 20 | K37: =+I37*J37 -> 0
E38: =SUM(E25:E37) -> 2500 | H38: =SUM(H25:H37) -> 2500 | K38: =SUM(K25:K37) -> 2000
A41: 03 TN 3317 | B41: A/S - BUFF | C41: 0.5 | D41: =250*C41 -> 125 | E41: =+C41*D41 -> 62.5 | F41: 25 | G41: =+E41*F41 -> 1562.5
A42: 132 D 23712 | B42: A/S - RED | C42: 0.5 | D42: =250*C42 -> 125 | E42: =+C42*D42 -> 62.5 | F42: 25 | G42: =+E42*F42 -> 1562.5
A43: 06 TN 2651 | B43: Cats Eyes | C43: 1 | E43: =+D43*C43 -> 0
A45: Note: Material in 25kgs , 40 bags = 1 Tonne
